<?xml version="1.0"?>
<robot xmlns:xacro="http://www.ros.org/wiki/xacro">
 
  <xacro:macro name="capstone" params="prefix">

    <!-- Define the world link -->
    <link name="${prefix}world"/>

    <!-- Define the box -->
    <link name="${prefix}box_link">
      <visual>
        <geometry>
          <box size="0.1 0.1 0.1"/>
        </geometry>
      </visual>
      <collision>
        <geometry>
          <box size="0.1 0.1 0.1"/>
        </geometry>
      </collision>
      <inertial>
        <origin xyz="0 0 0" />
        <mass value="1.0" />
        <inertia ixx="0.001" ixy="0.0" ixz="0.0" iyy="0.001" iyz="0.0" izz="0.001"/>
      </inertial>
    </link>

    <!-- Define the stick -->
    <link name="${prefix}stick_link">
      <visual>
        <geometry>
          <cylinder length="0.1" radius="0.01"/>
        </geometry>
      </visual>
      <collision>
        <geometry>
          <cylinder length="0.1" radius="0.01"/>
        </geometry>
      </collision>
      <inertial>
        <origin xyz="0 0 0.0" />
        <mass value="0.1" />
        <inertia ixx="0.0001" ixy="0.0" ixz="0.0" iyy="0.0001" iyz="0.0" izz="0.0001"/>
      </inertial>
    </link>

    <!-- Define the box on the stick -->
    <link name="${prefix}box_on_stick_link">
      <visual>
        <geometry>
          <box size="0.05 0.05 0.01"/>
        </geometry>
      </visual>
      <collision>
        <geometry>
          <box size="0.05 0.05 0.01"/>
        </geometry>
      </collision>
      <inertial>
        <origin xyz="0 0 0" />
        <mass value="0.05" />
        <inertia ixx="0.00001" ixy="0.0" ixz="0.0" iyy="0.00001" iyz="0.0" izz="0.00001"/>
      </inertial>
    </link>

    <!-- Define the fixed joint connecting the box to the world -->
    <joint name="${prefix}fixed_joint" type="fixed">
      <parent link="${prefix}world"/>
      <child link="${prefix}box_link"/>
      <origin xyz="0 0 0.1"/>
    </joint>

    <!-- Define the revolute joint connecting the stick to the box -->
    <joint name="${prefix}left_wheel_joint" type="continuous">
      <parent link="${prefix}box_link"/>
      <child link="${prefix}stick_link"/>
      <origin xyz="0 0 0.1"/>
      <axis xyz="0 0 1"/>
    </joint>

    <!-- Define the fixed joint connecting the box on the stick -->
    <joint name="${prefix}fixed_joint_box_on_stick" type="fixed">
      <parent link="${prefix}stick_link"/>
      <child link="${prefix}box_on_stick_link"/>
      <origin xyz="0.025 0 0.1"/>
    </joint>

  </xacro:macro>

</robot>
